Workbook

Sheet LD-ELFA
D1: (Atualização de Carga) LISTA DE DOCUMENTOS
A4: ITEM | B4: OSE | C4: DISCIPLINA | D4: TIPO DOCUMENTO | E4: REVDOC_ID | F4: Nº DOCUMENTO EMPRESA | G4: REV.: EMPRESA | H4: Nº DOCUMENTO CLIENTE | I4: REV.: CLIENTE | J4: FORMATO | K4: A1EQ | L4: FOLHAS | M4: AVANÇO FÍSICO | N4: FINALIDADE | O4: TITULO 1 | P4: TITULO 2 | Q4: TITULO 3 | R4: TITULO 4 | S4: TITULO 5 | T4: Nº GRD EMISSÃO | U4: DATA GRD EMISSÃO | V4: FINALIDADE RETORNO | W4: DATA COMENTARIO CLIENTE | X4: STATUS DO DOCUMENTO (Incluído, Conforme Aprovado ou Cancelado) | Y4: ITEM ESPEC. COD. | Z4: ID CRONOGRAMA | AA4: INICIO BL | AB4: EM. INICIAL BL | AC4: INÍCIO TENDÊNCIA | AD4: EMISSÃO INICIAL TENDÊNCIA | AE4: RETORNO CLIENTE | AF4: EMISSÃO FINAL TENDÊNCIA | AG4: INICIO REAL | AH4: REV SE | AI4: FORMATO BL | AJ4: Nº FOLHAS BL | AK4: A1EQ BL | AL4: DATA PERÍODO DE MEDIÇÃO | AM4: DATA AUXILIAR 1 | AN4: DATA AUXILIAR 2 | AO4: LOCAL | AP4: ITEM MEDIÇÃO | AQ4: AVANÇO FINANCEIRO | AR4: AVANÇO FINANCEIRO ACUMULADO | AS4: HORAS BL | AT4: HORAS EXECUTADAS | AU4: R$ BL | AV4: R$ REAL | AW4: OBSERVAÇÃO | AX4: PROVEDOR EXTERNO | AY4: STATUS PENDÊNCIA | AZ4: PENDÊNCIA | BA4: ORIGEM DOC | BB4: STATUS EXECUÇÂO | BC4: DATA PREVISTA EMISSÃO
A5: 1 | C5: AI - Automacao E Instrumentacao | D5: DPR - Diagrama De Projeto | E5: 93b23800-e180-492f-b873-8073e0dc14dd | F5: BL1132-0001-AI-DPR-2002 | G5: 0 | H5: DE-A1-2000-J-PB-0002 | I5: carol | J5: carol | K5: carol | L5: carol | M5: carol | N5: carol | O5: carol | P5: carol | Q5: carol | R5: carol | S5: carol | T5: carol | U5: carol | V5: carol | W5: carol | X5: carol | Y5: carol | Z5: carol | AA5: carol | AB5: carol | AC5: carol | AD5: carol | AE5: carol | AF5: carol | AG5: carol | AH5: carol | AI5: carol | AJ5: carol | AK5: carol | AL5: carol | AM5: carol | AN5: carol | AO5: carol | AP5: carol | AQ5: carol | AR5: carol | AS5: carol | AT5: carol | AU5: carol | AV5: carol | AW5: carol | AX5: carol | AY5: carol | AZ5: carol | BA5: carol | BB5: carol | BC5: carol
A6: 2 | C6: AI - Automacao E Instrumentacao | D6: DPR - Diagrama De Projeto | E6: 58f7e9fc-748a-4e5b-aee0-21bd92766a9a | F6: BL1132-0001-AI-DPR-2003 | G6: 0 | H6: DE-A1-2000-J-PB-0003 | J6: A1 | K6: 1 | L6: 1 | M6: 0.2 | O6: PROJETO BÁSICO | P6: SISTEMA AUTOMAÇÃO/COMUM | Q6: DIAGRAMA DE CONFIGURAÇÃO SAS/SGE | X6: Conforme Proposto | Z6: 731 | AA6: 46212 | AB6: 46217 | AC6: 46212 | AD6: 46217 | AE6: 46227 | AF6: 46232 | AG6: 46212 | AH6: 0 | AK6: 0 | AL6: carol | AM6: carol | AN6: carol | AO6: Belo Horizonte | AP6: N.A | AQ6: carol | AR6: carol | AT6: 8:00 | AU6: carol | AV6: carol | AW6: carol | AX6: N/A - NÃO SE APLICA | AY6: carol | AZ6: carol | BA6: 2D | BB6: A | BC6: carol
A7: 3 | C7: AI - Automacao E Instrumentacao | D7: DPR - Diagrama De Projeto | E7: a8dbe6d4-e801-4fb6-b2a3-5150eecfb749 | F7: BL1132-0001-AI-DPR-2004 | G7: 0 | H7: DE-A1-2000-J-PB-0004 | J7: A1 | K7: 1 | L7: 1 | M7: 0 | O7: PROJETO BÁSICO | P7: OUTROS SISTEMAS | Q7: DIAGRAMA DE CONFIGURAÇÃO DE TELECOM | R7: SDACI | X7: Conforme Proposto | Z7: 849 | AA7: 46247 | AB7: 46252 | AC7: 46247 | AD7: 46252 | AE7: 46262 | AF7: 46267 | AH7: 0 | AK7: 0 | AL7: carol | AM7: carol | AN7: carol | AO7: Belo Horizonte | AP7: N.A | AQ7: carol | AR7: carol | AU7: carol | AV7: carol | AW7: carol | AX7: N/A - NÃO SE APLICA | AY7: carol | AZ7: carol | BA7: 2D | BB7: A | BC7: carol
A8: 4 | C8: AI - Automacao E Instrumentacao | D8: DPR - Diagrama De Projeto | E8: c31b4d58-bf1b-436a-ae07-75cfb2d0c3fb | F8: BL1132-0001-AI-DPR-2005 | G8: 0 | H8: DE-A1-2000-J-PB-0005 | J8: A1 | K8: 1 | L8: 1 | M8: 0 | O8: PROJETO BÁSICO | P8: OUTROS SISTEMAS | Q8: DIAGRAMA DE CONFIGURAÇÃO DE TELECOM | R8: REDE DE DADOS E TELEFONIA | X8: Conforme Proposto | Z8: 900 | AA8: 46239 | AB8: 46244 | AC8: 46239 | AD8: 46244 | AE8: 46254 | AF8: 46259 | AH8: 0 | AK8: 0 | AL8: carol | AM8: carol | AN8: carol | AO8: Belo Horizonte | AP8: N.A | AQ8: carol | AR8: carol | AU8: carol | AV8: carol | AW8: carol | AX8: N/A - NÃO SE APLICA | AY8: carol | AZ8: carol | BA8: 2D | BB8: A | BC8: carol
A9: 5 | C9: AI - Automacao E Instrumentacao | D9: DPR - Diagrama De Projeto | E9: 6f79b2a4-dfeb-4c1a-9ca8-1cd80491b052 | F9: BL1132-0001-AI-DPR-2006 | G9: 0 | H9: DE-A1-2000-J-PB-0006 | J9: A1 | K9: 1 | L9: 1 | M9: 0 | O9: PROJETO BÁSICO | P9: OUTROS SISTEMAS | Q9: DIAGRAMA DE CONFIGURAÇÃO DE TELECOM | R9: SEGURANÇA PATRIMONIAL | X9: Inserido | Z9: 882 | AA9: 46233 | AB9: 46237 | AC9: 46233 | AD9: 46237 | AE9: 46247 | AF9: 46252 | AH9: 0 | AK9: 0 | AL9: carol | AM9: carol | AN9: carol | AO9: Belo Horizonte | AP9: N.A | AQ9: carol | AR9: carol | AU9: carol | AV9: carol | AW9: carol | AX9: N/A - NÃO SE APLICA | AY9: carol | AZ9: carol | BA9: 2D | BB9: A | BC9: carol
A10: 6 | C10: AI - Automacao E Instrumentacao | D10: DPR - Diagrama De Projeto | E10: 08771502-7214-4041-ab84-fdcee2a18e3e | F10: BL1132-0001-AI-DPR-2007 | G10: 0 | H10: DE-A1-2000-J-PB-0007 | J10: A1 | K10: 1 | L10: 1 | M10: 0 | O10: PROJETO BÁSICO | P10: OUTROS SISTEMAS | Q10: DIAGRAMA DE CONFIGURAÇÃO DE TELECOM | R10: CFTV PROCESSO | X10: Inserido | Z10: 867 | AA10: 46227 | AB10: 46231 | AC10: 46227 | AD10: 46231 | AE10: 46241 | AF10: 46246 | AH10: 0 | AK10: 0 | AL10: carol | AM10: carol | AN10: carol | AO10: Belo Horizonte | AP10: N.A | AQ10: carol | AR10: carol | AU10: carol | AV10: carol | AW10: carol | AX10: N/A - NÃO SE APLICA | AY10: carol | AZ10: carol | BA10: 2D | BB10: A | BC10: carol
A11: 7 | C11: AI - Automacao E Instrumentacao | D11: DPR - Diagrama De Projeto | E11: 4641aae2-a3f0-4e7e-a3c8-4cadbd3dfe80 | F11: BL1132-0001-AI-DPR-2008 | G11: 0 | H11: DE-A1-2006-J-PB-0001 | J11: A1 | K11: 1 | L11: 1 | M11: 0 | O11: PROJETO BÁSICO | P11: OUTROS SISTEMAS | Q11: DIAGRAMA DE CONFIGURAÇÃO DE TELECOM | R11: BACKBONE TI | X11: Inserido | Z11: 910 | AA11: 46244 | AB11: 46247 | AC11: 46244 | AD11: 46247 | AE11: 46257 | AF11: 46262 | AH11: 0 | AK11: 0 | AL11: carol | AM11: carol | AN11: carol | AO11: Belo Horizonte | AP11: N.A | AQ11: carol | AR11: carol | AU11: carol | AV11: carol | AW11: carol | AX11: N/A - NÃO SE APLICA | AY11: carol | AZ11: carol | BA11: 2D | BB11: A | BC11: carol
A12: 8 | C12: AI - Automacao E Instrumentacao | D12: ETE - Especificação Técnica | E12: 6f4a2f84-aa94-4289-94d8-d52485445ebd | F12: BL1132-0001-AI-ETE-2001 | G12: 0 | H12: ET-A1-2000-J-PB-0002 | J12: A4 | K12: 2.5 | L12: 20 | M12: 0 | O12: PROJETO BÁSICO | P12: SISTEMA DE AUTOMAÇÃO/OUTROS SISTEMAS | Q12: ESPECIFICAÇÃO TÉCNICA | R12: SISTEMA DE CONTROLE E AUTOMAÇÃO | X12: Conforme Proposto | Z12: 756 | AA12: 46225 | AB12: 46226 | AC12: 46225 | AD12: 46226 | AE12: 46236 | AF12: 46241 | AH12: 0 | AK12: 0 | AL12: carol | AM12: carol | AN12: carol | AO12: Belo Horizonte | AP12: N.A | AQ12: carol | AR12: carol | AU12: carol | AV12: carol | AW12: carol | AX12: N/A - NÃO SE APLICA | AY12: carol | AZ12: carol | BA12: 2D | BB12: A | BC12: carol
A13: 9 | C13: AI - Automacao E Instrumentacao | D13: ETE - Especificação Técnica | E13: f3aa54ea-2f58-4ae8-a85a-1466608c1d05 | F13: BL1132-0001-AI-ETE-2002 | G13: 0 | H13: ET-A1-2006-J-PB-0002 | J13: A4 | K13: 2 | L13: 16 | M13: 0 | O13: PROJETO BÁSICO | P13: SISTEMA DE AUTOMAÇÃO/OUTROS SISTEMAS | Q13: ESPECIFICAÇÃO TÉCNICA | R13: SDACI | X13: Conforme Proposto | Z13: 859 | AA13: 46248 | AB13: 46252 | AC13: 46248 | AD13: 46252 | AE13: 46262 | AF13: 46267 | AH13: 0 | AK13: 0 | AL13: carol | AM13: carol | AN13: carol | AO13: Belo Horizonte | AP13: N.A | AQ13: carol | AR13: carol | AU13: carol | AV13: carol | AW13: carol | AX13: N/A - NÃO SE APLICA | AY13: carol | AZ13: carol | BA13: 2D | BB13: A | BC13: carol
A14: 10 | C14: AI - Automacao E Instrumentacao | D14: ETE - Especificação Técnica | E14: 13d81575-8b3b-4ab2-9195-7d00258274e4 | F14: BL1132-0001-AI-ETE-2003 | G14: 0 | H14: ET-A1-2006-J-PB-0004 | J14: A4 | K14: 2 | L14: 16 | M14: 0 | O14: PROJETO BÁSICO | P14: SISTEMA DE AUTOMAÇÃO/OUTROS SISTEMAS | Q14: ESPECIFICAÇÃO TÉCNICA | R14: SEGURANÇA PATRIMONIAL | X14: Conforme Proposto | Z14: 892 | AA14: 46237 | AB14: 46239 | AC14: 46237 | AD14: 46239 | AE14: 46249 | AF14: 46254 | AH14: 0 | AK14: 0 | AL14: carol | AM14: carol | AN14: carol | AO14: Belo Horizonte | AP14: N.A | AQ14: carol | AR14: carol | AU14: carol | AV14: carol | AW14: carol | AX14: N/A - NÃO SE APLICA | AY14: carol | AZ14: carol | BA14: 2D | BB14: A | BC14: carol
A15: 11 | C15: AI - Automacao E Instrumentacao | D15: ETE - Especificação Técnica | E15: 413ef93f-e0a7-499a-8866-1d31806ce52e | F15: BL1132-0001-AI-ETE-2004 | G15: 0 | H15: ET-A1-2007-J-PB-0001 | J15: A4 | K15: 2 | L15: 16 | M15: 0 | O15: PROJETO BÁSICO | P15: MONITORAMENTO DE PROCESSO - CFTV | Q15: ESPECIFICAÇÃO TÉCNICA | R15: CFTV DE PROCESSO | X15: Conforme Proposto | Z15: 877 | AA15: 46231 | AB15: 46233 | AC15: 46231 | AD15: 46233 | AE15: 46243 | AF15: 46248 | AH15: 0 | AK15: 0 | AL15: carol | AM15: carol | AN15: carol | AO15: Belo Horizonte | AP15: N.A | AQ15: carol | AR15: carol | AU15: carol | AV15: carol | AW15: carol | AX15: N/A - NÃO SE APLICA | AY15: carol | AZ15: carol | BA15: 2D | BB15: A | BC15: carol
A16: 12 | C16: AI - Automacao E Instrumentacao | D16: FDA - Folha De Dados | E16: d100465d-5452-46bf-8060-843afa91e71a | F16: BL1132-0001-AI-FDA-2000 | G16: 0 | H16: FD-A1-2000-J-PB-0001 | J16: A4 | K16: 4 | L16: 32 | M16: 0 | O16: PROJETO BÁSICO | P16: SISTEMA AUTOMAÇÃO/COMUM | Q16: FOLHA DE DADOS | R16: BALANÇA RODOVIÁRIA | X16: Conforme Proposto | Z16: 766 | AA16: 46254 | AB16: 46255 | AC16: 46254 | AD16: 46255 | AE16: 46265 | AF16: 46270 | AH16: 0 | AK16: 0 | AL16: carol | AM16: carol | AN16: carol | AO16: Belo Horizonte | AP16: N.A | AQ16: carol | AR16: carol | AU16: carol | AV16: carol | AW16: carol | AX16: N/A - NÃO SE APLICA | AY16: carol | AZ16: carol | BA16: 2D | BB16: A | BC16: carol
A17: 13 | C17: AI - Automacao E Instrumentacao | D17: FDA - Folha De Dados | E17: 12cf9b7a-309b-41b9-8e38-8b7c8f1f1aac | F17: BL1132-0001-AI-FDA-2001 | G17: 0 | H17: FD-A1-2000-J-PB-0002 | J17: A4 | K17: 1 | L17: 8 | M17: 0 | O17: PROJETO BÁSICO | P17: SISTEMA AUTOMAÇÃO/COMUM | Q17: FOLHA DE DADOS | R17: SISTEMA SUPERVISÃO DE CONTROLE DE PROCESSOS | X17: Conforme Proposto | Z17: 741 | AA17: 46217 | AB17: 46220 | AC17: 46217 | AD17: 46220 | AE17: 46230 | AF17: 46235 | AH17: 0 | AK17: 0 | AL17: carol | AM17: carol | AN17: carol | AO17: Belo Horizonte | AP17: N.A | AQ17: carol | AR17: carol | AU17: carol | AV17: carol | AW17: carol | AX17: N/A - NÃO SE APLICA | AY17: carol | AZ17: carol | BA17: 2D | BB17: A | BC17: carol
A18: 14 | C18: AI - Automacao E Instrumentacao | D18: FDA - Folha De Dados | E18: bde1966a-d5ee-42e0-bf81-a6d8ab001854 | F18: BL1132-0001-AI-FDA-2002 | G18: 1 | H18: FD-A1-2000-J-PB-0003 | I18: 2 | J18: A4 | K18: 0.75 | L18: 6 | M18: 1 | N18: PARA COTAÇÃO | O18: PROJETO BÁSICO | P18: SISTEMA AUTOMAÇÃO/COMUM | Q18: FOLHA DE DADOS | R18: MEDIDOR DE NÍVEL TIPO RADAR | T18: 0021 | U18: 46210.679 | V18: APR - APROVADO | W18: 46212.67 | X18: Conforme Proposto | Z18: 691 | AA18: 46196 | AB18: 46199 | AD18: 46210.679 | AE18: 46210.679 | AF18: 46210.679 | AG18: 46190 | AK18: 0 | AL18: carol | AM18: carol | AN18: carol | AO18: Belo Horizonte | AP18: N.A | AQ18: carol | AR18: carol | AT18: 9:00 | AU18: carol | AV18: carol | AW18: carol | AX18: N/A - NÃO SE APLICA | AY18: carol | AZ18: carol | BA18: 2D | BB18: A | BC18: 46209
A19: 15 | C19: AI - Automacao E Instrumentacao | D19: FDA - Folha De Dados | E19: fa3902b2-8040-442c-bc93-74778ab47b8f | F19: BL1132-0001-AI-FDA-2003 | G19: 0 | H19: FD-A1-2000-J-PB-0004 | J19: A4 | K19: 4 | L19: 32 | M19: 0 | O19: PROJETO BÁSICO | P19: SISTEMA AUTOMAÇÃO/COMUM | Q19: FOLHA DE DADOS | R19: MEDIDOR DE VAZÃO MAGNÉTICO | X19: Conforme Proposto | Z19: 806 | AA19: 46259 | AB19: 46265 | AC19: 46259 | AD19: 46265 | AE19: 46275 | AF19: 46280 | AH19: 0 | AK19: 0 | AL19: carol | AM19: carol | AN19: carol | AO19: Belo Horizonte | AP19: N.A | AQ19: carol | AR19: carol | AU19: carol | AV19: carol | AW19: carol | AX19: N/A - NÃO SE APLICA | AY19: carol | AZ19: carol | BA19: 2D | BB19: A
A20: 16 | C20: AI - Automacao E Instrumentacao | D20: FDA - Folha De Dados | E20: f9cd5c0f-066e-4cbb-a664-54bbd9b158a6 | F20: BL1132-0001-AI-FDA-2004 | G20: 0 | H20: FD-A1-2000-J-PB-0005 | J20: A4 | K20: 1 | L20: 8 | M20: 0 | O20: PROJETO BÁSICO | P20: SISTEMA AUTOMAÇÃO/COMUM | Q20: FOLHA DE DADOS | R20: MEDIDOR DE TEMPERATURA | X20: Conforme Proposto | Z20: 811 | AA20: 46259 | AB20: 46265 | AC20: 46259 | AD20: 46265 | AE20: 46275 | AF20: 46280 | AH20: 0 | AK20: 0 | AL20: carol | AM20: carol | AN20: carol | AO20: Belo Horizonte | AP20: N.A | AQ20: carol | AR20: carol | AU20: carol | AV20: carol | AW20: carol | AX20: N/A - NÃO SE APLICA | AY20: carol | AZ20: carol | BA20: 2D | BB20: A
A21: 17 | C21: AI - Automacao E Instrumentacao | D21: FDA - Folha De Dados | E21: d9564a92-2ad7-45ff-a03a-bd12ec83597f | F21: BL1132-0001-AI-FDA-2005 | G21: 0 | H21: FD-A1-2000-J-PB-0006 | J21: A4 | K21: 1 | L21: 8 | M21: 0 | O21: PROJETO BÁSICO | P21: SISTEMA AUTOMAÇÃO/COMUM | Q21: FOLHA DE DADOS | R21: MEDIDOR DE PRESSÃO | X21: Conforme Proposto | Z21: 816 | AA21: 46265 | AB21: 46269 | AC21: 46265 | AD21: 46269 | AE21: 46279 | AF21: 46284 | AH21: 0 | AK21: 0 | AL21: carol | AM21: carol | AN21: carol | AO21: Belo Horizonte | AP21: N.A | AQ21: carol | AR21: carol | AU21: carol | AV21: carol | AW21: carol | AX21: N/A - NÃO SE APLICA | AY21: carol | AZ21: carol | BA21: 2D | BB21: A
A22: 18 | C22: AI - Automacao E Instrumentacao | D22: FDA - Folha De Dados | E22: 2418ad00-e84f-4341-aa91-e15a5d55465d | F22: BL1132-0001-AI-FDA-2006 | G22: 0 | H22: FD-A1-2000-J-PB-0007 | J22: A4 | K22: 1 | L22: 8 | M22: 0 | O22: PROJETO BÁSICO | P22: SISTEMA AUTOMAÇÃO/COMUM | Q22: FOLHA DE DADOS | R22: VÁLVULA AUTO-OPERADA | X22: Conforme Proposto | Z22: 781 | AA22: 46255 | AB22: 46258 | AC22: 46255 | AD22: 46258 | AE22: 46268 | AF22: 46273 | AH22: 0 | AK22: 0 | AL22: carol | AM22: carol | AN22: carol | AO22: Belo Horizonte | AP22: N.A | AQ22: carol | AR22: carol | AU22: carol | AV22: carol | AW22: carol | AX22: N/A - NÃO SE APLICA | AY22: carol | AZ22: carol | BA22: 2D | BB22: A
A23: 19 | C23: AI - Automacao E Instrumentacao | D23: FDA - Folha De Dados | E23: 53d77677-a0fa-422e-b85f-970c183db5db | F23: BL1132-0001-AI-FDA-2007 | G23: 0 | H23: FD-A1-2000-J-PB-0008 | J23: A4 | K23: 1 | L23: 8 | M23: 0 | O23: PROJETO BÁSICO | P23: SISTEMA AUTOMAÇÃO/COMUM | Q23: FOLHA DE DADOS | R23: VÁLVULA ON-OFF | X23: Conforme Proposto | Z23: 776 | AA23: 46255 | AB23: 46258 | AC23: 46255 | AD23: 46258 | AE23: 46268 | AF23: 46273 | AH23: 0 | AK23: 0 | AL23: carol | AM23: carol | AN23: carol | AO23: Belo Horizonte | AP23: N.A | AQ23: carol | AR23: carol | AU23: carol | AV23: carol | AW23: carol | AX23: N/A - NÃO SE APLICA | AY23: carol | AZ23: carol | BA23: 2D | BB23: A
A24: 20 | C24: AI - Automacao E Instrumentacao | D24: FDA - Folha De Dados | E24: e7444e53-3ead-4e66-984e-e3b4bece776a | F24: BL1132-0001-AI-FDA-2008 | G24: 0 | H24: FD-A1-2000-J-PB-0009 | J24: A4 | K24: 1 | L24: 8 | M24: 0 | O24: PROJETO BÁSICO | P24: SISTEMA AUTOMAÇÃO/COMUM | Q24: FOLHA DE DADOS | R24: BALANÇA INTEGRADORA | X24: Conforme Proposto | Z24: 831 | AA24: 46269 | AB24: 46275 | AC24: 46269 | AD24: 46275 | AE24: 46285 | AF24: 46290 | AH24: 0 | AK24: 0 | AL24: carol | AM24: carol | AN24: carol | AO24: Belo Horizonte | AP24: N.A | AQ24: carol | AR24: carol | AU24: carol | AV24: carol | AW24: carol | AX24: N/A - NÃO SE APLICA | AY24: carol | AZ24: carol | BA24: 2D | BB24: A
A25: 21 | C25: AI - Automacao E Instrumentacao | D25: FDA - Folha De Dados | E25: 73df8b89-ff29-4b64-8931-2e641d10fca8 | F25: BL1132-0001-AI-FDA-2009 | G25: 0 | H25: FD-A1-2000-J-PB-0010 | J25: A4 | K25: 1 | L25: 8 | M25: 0 | O25: PROJETO BÁSICO | P25: SISTEMA AUTOMAÇÃO/COMUM | Q25: FOLHA DE DADOS | R25: ANALISADOR DE CONDUTIVIDADE | X25: Conforme Proposto | Z25: 836 | AA25: 46269 | AB25: 46275 | AC25: 46269 | AD25: 46275 | AE25: 46285 | AF25: 46290 | AH25: 0 | AK25: 0 | AL25: carol | AM25: carol | AN25: carol | AO25: Belo Horizonte | AP25: N.A | AQ25: carol | AR25: carol | AU25: carol | AV25: carol | AW25: carol | AX25: N/A - NÃO SE APLICA | AY25: carol | AZ25: carol | BA25: 2D | BB25: A
A26: 22 | C26: AI - Automacao E Instrumentacao | D26: FDA - Folha De Dados | E26: 709744f9-8305-4d80-bb42-567b796ed6b3 | F26: BL1132-0001-AI-FDA-2010 | G26: 0 | H26: FD-A1-2000-J-PB-0011 | J26: A4 | K26: 1 | L26: 8 | M26: 0 | O26: PROJETO BÁSICO | P26: SISTEMA AUTOMAÇÃO/COMUM | Q26: FOLHA DE DADOS | R26: ANALISADOR DE pH | X26: Conforme Proposto | Z26: 841 | AA26: 46269 | AB26: 46275 | AC26: 46269 | AD26: 46275 | AE26: 46285 | AF26: 46290 | AH26: 0 | AK26: 0 | AL26: carol | AM26: carol | AN26: carol | AO26: Belo Horizonte | AP26: N.A | AQ26: carol | AR26: carol | AU26: carol | AV26: carol | AW26: carol | AX26: N/A - NÃO SE APLICA | AY26: carol | AZ26: carol | BA26: 2D | BB26: A
A27: 23 | C27: AI - Automacao E Instrumentacao | D27: FDA - Folha De Dados | E27: 1b1dfe55-42eb-4d37-a8d5-accd11dd0f6e | F27: BL1132-0001-AI-FDA-2011 | G27: 0 | H27: FD-A1-2000-J-PB-0012 | I27: 1 | J27: A4 | K27: 0.375 | L27: 3 | M27: 1 | N27: CANCELADO | O27: PROJETO BÁSICO | P27: SISTEMA AUTOMAÇÃO/COMUM | Q27: FOLHA DE DADOS | R27: CHAVE DE NÍVEL PORTINHOLA | T27: 0007 | U27: 46202.538 | V27: APR - APROVADO | W27: 46205.376 | X27: Conforme Proposto | Z27: 696 | AA27: 46199 | AB27: 46204 | AC27: 46197 | AD27: 46202.538 | AE27: 46202.538 | AF27: 46202.538 | AG27: 46191 | AH27: 0 | AK27: 0 | AL27: carol | AM27: carol | AN27: carol | AO27: Belo Horizonte | AP27: N.A | AQ27: carol | AR27: carol | AT27: 3:45 | AU27: carol | AV27: carol | AW27: carol | AX27: N/A - NÃO SE APLICA | AY27: carol | AZ27: carol | BA27: 2D | BB27: A
A28: 24 | C28: AI - Automacao E Instrumentacao | D28: FDA - Folha De Dados | E28: c74e302c-cc1e-449e-8474-6bc5aa09110d | F28: BL1132-0001-AI-FDA-2012 | G28: 0 | H28: FD-A1-2000-J-PB-0013 | J28: A4 | K28: 1 | L28: 8 | M28: 0.2 | O28: PROJETO BÁSICO | P28: SISTEMA AUTOMAÇÃO/COMUM | Q28: FOLHA DE DADOS | R28: MANÔMETRO | X28: Conforme Proposto | Z28: 826 | AA28: 46269 | AB28: 46275 | AC28: 46269 | AD28: 46275 | AE28: 46285 | AF28: 46290 | AG28: 46191 | AH28: 0 | AK28: 0 | AL28: carol | AM28: carol | AN28: carol | AO28: Belo Horizonte | AP28: N.A | AQ28: carol | AR28: carol | AT28: 3:00 | AU28: carol | AV28: carol | AW28: carol | AX28: N/A - NÃO SE APLICA | AY28: carol | AZ28: carol | BA28: 2D | BB28: A
A29: 25 | C29: AI - Automacao E Instrumentacao | D29: FDA - Folha De Dados | E29: 3ebcff8f-94ff-45a2-b3d0-148876939917 | F29: BL1132-0001-AI-FDA-2013 | G29: 0 | H29: FD-A1-2000-J-PB-0014 | I29: 1 | J29: A4 | K29: 1.125 | L29: 9 | M29: 0.9 | N29: PARA APROVAÇÃO | O29: PROJETO BÁSICO | P29: SISTEMA AUTOMAÇÃO/COMUM | Q29: FOLHA DE DADOS | R29: PAINEL PNEUMÁTICO | T29: 0021 | U29: 46210.679 | V29: APC-L - APC-L - Aprovado com Comentários (Retornar Aprovado) | W29: 46213.602 | X29: Conforme Proposto | Z29: 716 | AA29: 46204 | AB29: 46209 | AC29: 46204 | AD29: 46210.679 | AE29: 46220.679 | AF29: 46225.679 | AG29: 46203 | AH29: 0 | AK29: 0 | AL29: carol | AM29: carol | AN29: carol | AO29: Belo Horizonte | AP29: N.A | AQ29: carol | AR29: carol | AT29: 11:15 | AU29: carol | AV29: carol | AW29: carol | AX29: N/A - NÃO SE APLICA | AY29: carol | AZ29: carol | BA29: 2D | BB29: A
A30: 26 | C30: AI - Automacao E Instrumentacao | D30: FDA - Folha De Dados | E30: d257d034-3eb6-4f21-a21e-94a7f937f2d0 | F30: BL1132-0001-AI-FDA-2014 | G30: 1 | H30: FD-A1-2000-J-PB-0015 | I30: 2 | J30: A4 | K30: 0.5 | L30: 4 | M30: 1 | N30: CANCELADO | O30: PROJETO BÁSICO | P30: SISTEMA AUTOMAÇÃO/COMUM | Q30: FOLHA DE DADOS | R30: SENSOR DE POSIÇÃO | T30: 0021 | U30: 46210.679 | V30: CLD - CANCELADO | W30: 46212.679 | X30: Conforme Proposto | Z30: 701 | AA30: 46199 | AB30: 46204 | AD30: 46210.679 | AE30: 46210.679 | AF30: 46210.679 | AG30: 46192 | AK30: 0 | AL30: carol | AM30: carol | AN30: carol | AO30: Belo Horizonte | AP30: N.A | AQ30: carol | AR30: carol | AT30: 6:00 | AU30: carol | AV30: carol | AW30: carol | AX30: N/A - NÃO SE APLICA | AY30: carol | AZ30: carol | BA30: 2D | BB30: A | BC30: 46209
A31: 27 | C31: AI - Automacao E Instrumentacao | D31: FDA - Folha De Dados | E31: 19839216-f05b-48e6-b1f9-6149c042bf7a | F31: BL1132-0001-AI-FDA-2015 | G31: 1 | H31: FD-A1-2000-J-PB-0016 | I31: 2 | J31: A4 | K31: 0.375 | L31: 3 | M31: 1 | N31: PARA COTAÇÃO | O31: PROJETO BÁSICO | P31: SISTEMA AUTOMAÇÃO/COMUM | Q31: FOLHA DE DADOS | R31: SINALIZADOR LUMINOSO | T31: 0033 | U31: 46213.7 | X31: Conforme Proposto | Z31: 706 | AA31: 46204 | AB31: 46209 | AD31: 46213.7 | AE31: 46213.7 | AF31: 46213.7 | AG31: 46199 | AK31: 0 | AL31: carol | AM31: carol | AN31: carol | AO31: Belo Horizonte | AP31: N.A | AQ31: carol | AR31: carol | AT31: 5:00 | AU31: carol | AV31: carol | AW31: carol | AX31: N/A - NÃO SE APLICA | AY31: carol | AZ31: carol | BA31: 2D | BB31: A
A32: 28 | C32: AI - Automacao E Instrumentacao | D32: FDA - Folha De Dados | E32: 87c357dd-e204-4c4e-8fa4-31aeda8d06c8 | F32: BL1132-0001-AI-FDA-2016 | G32: 0 | H32: FD-A1-2000-J-PB-0017 | J32: A4 | K32: 1 | L32: 8 | M32: 0 | O32: PROJETO BÁSICO | P32: SISTEMA AUTOMAÇÃO/COMUM | Q32: FOLHA DE DADOS | R32: VÁLVULA DE ALÍVIO DE PRESSÃO | X32: Conforme Proposto | Z32: 786 | AA32: 46258 | AB32: 46259 | AC32: 46258 | AD32: 46259 | AE32: 46269 | AF32: 46274 | AH32: 0 | AK32: 0 | AL32: carol | AM32: carol | AN32: carol | AO32: Belo Horizonte | AP32: N.A | AQ32: carol | AR32: carol | AU32: carol | AV32: carol | AW32: carol | AX32: N/A - NÃO SE APLICA | AY32: carol | AZ32: carol | BA32: 2D | BB32: A
A33: 29 | C33: AI - Automacao E Instrumentacao | D33: FDA - Folha De Dados | E33: 353a3859-66b1-4af6-9ff4-dad49e08fb4c | F33: BL1132-0001-AI-FDA-2017 | G33: 0 | H33: FD-A1-2000-J-PB-0018 | J33: A4 | K33: 1 | L33: 8 | M33: 0 | O33: PROJETO BÁSICO | P33: SISTEMA AUTOMAÇÃO/COMUM | Q33: FOLHA DE DADOS | R33: VÁLVULA DE CONTROLE - ESFERA | X33: Conforme Proposto | Z33: 771 | AA33: 46254 | AB33: 46255 | AC33: 46254 | AD33: 46255 | AE33: 46265 | AF33: 46270 | AH33: 0 | AK33: 0 | AL33: carol | AM33: carol | AN33: carol | AO33: Belo Horizonte | AP33: N.A | AQ33: carol | AR33: carol | AU33: carol | AV33: carol | AW33: carol | AX33: N/A - NÃO SE APLICA | AY33: carol | AZ33: carol | BA33: 2D | BB33: A
A34: 30 | C34: AI - Automacao E Instrumentacao | D34: FDA - Folha De Dados | E34: 9f6dca80-0bd8-4984-8778-ea9281243dbb | F34: BL1132-0001-AI-FDA-2018 | G34: 0 | H34: FD-A1-2000-J-PB-0019 | J34: A4 | K34: 1 | L34: 8 | M34: 0 | O34: PROJETO BÁSICO | P34: SISTEMA AUTOMAÇÃO/COMUM | Q34: FOLHA DE DADOS | R34: VÁLVULA DILÚVIO | X34: Conforme Proposto | Z34: 791 | AA34: 46258 | AB34: 46259 | AC34: 46258 | AD34: 46259 | AE34: 46269 | AF34: 46274 | AH34: 0 | AK34: 0 | AL34: carol | AM34: carol | AN34: carol | AO34: Belo Horizonte | AP34: N.A | AQ34: carol | AR34: carol | AU34: carol | AV34: carol | AW34: carol | AX34: N/A - NÃO SE APLICA | AY34: carol | AZ34: carol | BA34: 2D | BB34: A
A35: 31 | C35: AI - Automacao E Instrumentacao | D35: FDA - Folha De Dados | E35: cd12ff6e-2f17-4650-988b-36e35f1975c1 | F35: BL1132-0001-AI-FDA-2019 | G35: 0 | H35: FD-A1-2000-J-PB-0020 | J35: A4 | K35: 1 | L35: 8 | M35: 0 | O35: PROJETO BÁSICO | P35: SISTEMA AUTOMAÇÃO/COMUM | Q35: FOLHA DE DADOS | R35: VÁLVULA GOVERNO E ALARME | X35: Conforme Proposto | Z35: 796 | AA35: 46258 | AB35: 46259 | AC35: 46258 | AD35: 46259 | AE35: 46269 | AF35: 46274 | AH35: 0 | AK35: 0 | AL35: carol | AM35: carol | AN35: carol | AO35: Belo Horizonte | AP35: N.A | AQ35: carol | AR35: carol | AU35: carol | AV35: carol | AW35: carol | AX35: N/A - NÃO SE APLICA | AY35: carol | AZ35: carol | BA35: 2D | BB35: A
A36: 32 | C36: AI - Automacao E Instrumentacao | D36: FDA - Folha De Dados | E36: 57459f95-0d15-4ae0-a551-5b236654d61a | F36: BL1132-0001-AI-FDA-2020 | G36: 0 | H36: FD-A1-2000-J-PB-0021 | J36: A4 | K36: 1 | L36: 8 | M36: 0 | O36: PROJETO BÁSICO | P36: SISTEMA AUTOMAÇÃO/COMUM | Q36: FOLHA DE DADOS | R36: MEDIDOR DE VAZÃO VORTEX | X36: Conforme Proposto | Z36: 821 | AA36: 46265 | AB36: 46269 | AC36: 46265 | AD36: 46269 | AE36: 46279 | AF36: 46284 | AH36: 0 | AK36: 0 | AL36: carol | AM36: carol | AN36: carol | AO36: Belo Horizonte | AP36: N.A | AQ36: carol | AR36: carol | AU36: carol | AV36: carol | AW36: carol | AX36: N/A - NÃO SE APLICA | AY36: carol | AZ36: carol | BA36: 2D | BB36: A
A37: 33 | C37: AI - Automacao E Instrumentacao | D37: FDA - Folha De Dados | E37: 2e42e950-1b07-42f8-8442-da1626c10c30 | F37: BL1132-0001-AI-FDA-2021 | G37: 1 | H37: FD-A1-2000-J-PB-0022 | I37: 2 | J37: A4 | K37: 0.5 | L37: 4 | M37: 1 | N37: PARA COTAÇÃO | O37: PROJETO BÁSICO | P37: SISTEMA AUTOMAÇÃO/COMUM | Q37: FOLHA DE DADOS | R37: ANALISADOR CNA | T37: 0033 | U37: 46213.7 | X37: Conforme Proposto | Z37: 711 | AA37: 46204 | AB37: 46209 | AD37: 46213.7 | AE37: 46213.7 | AF37: 46213.7 | AG37: 46202 | AK37: 0 | AL37: carol | AM37: carol | AN37: carol | AO37: Belo Horizonte | AP37: N.A | AQ37: carol | AR37: carol | AT37: 5:00 | AU37: carol | AV37: carol | AW37: carol | AX37: N/A - NÃO SE APLICA | AY37: carol | AZ37: carol | BA37: 2D | BB37: A
A38: 34 | C38: AI - Automacao E Instrumentacao | D38: FDA - Folha De Dados | E38: 47ca7eb2-5fc4-4202-b471-b2f0f8da9c36 | F38: BL1132-0001-AI-FDA-2022 | G38: 0 | H38: FD-A1-2000-J-PB-0023 | J38: A4 | K38: 1 | L38: 8 | M38: 0 | O38: PROJETO BÁSICO | P38: SISTEMA AUTOMAÇÃO/COMUM | Q38: FOLHA DE DADOS | R38: VÁLVULA SOLENOIDE | X38: Conforme Proposto | Z38: 801 | AA38: 46254 | AB38: 46259 | AC38: 46254 | AD38: 46259 | AE38: 46269 | AF38: 46274 | AH38: 0 | AK38: 0 | AL38: carol | AM38: carol | AN38: carol | AO38: Belo Horizonte | AP38: N.A | AQ38: carol | AR38: carol | AU38: carol | AV38: carol | AW38: carol | AX38: N/A - NÃO SE APLICA | AY38: carol | AZ38: carol | BA38: 2D | BB38: A
A39: 35 | C39: AI - Automacao E Instrumentacao | D39: FDA - Folha De Dados | E39: 8a45a312-9775-454b-b191-694c288d92c2 | F39: BL1132-0001-AI-FDA-2023 | G39: 0 | H39: FD-A1-2004-J-PB-0001 | J39: A4 | K39: 1 | L39: 8 | M39: 0 | O39: PROJETO BÁSICO | P39: SISTEMA DE AUTOMAÇÃO / SISTEMA DE CONTROLE DE EMERGENCIA | Q39: FOLHA DE DADOS | R39: QDTI AUTOMAÇÃO | X39: Conforme Proposto | Z39: 751 | AA39: 46220 | AB39: 46225 | AC39: 46220 | AD39: 46225 | AE39: 46235 | AF39: 46240 | AH39: 0 | AK39: 0 | AL39: carol | AM39: carol | AN39: carol | AO39: Belo Horizonte | AP39: N.A | AQ39: carol | AR39: carol | AU39: carol | AV39: carol | AW39: carol | AX39: N/A - NÃO SE APLICA | AY39: carol | AZ39: carol | BA39: 2D | BB39: A
A40: 36 | C40: AI - Automacao E Instrumentacao | D40: FDA - Folha De Dados | E40: 44ad82cf-3d85-4c2a-98bb-c7bfece87905 | F40: BL1132-0001-AI-FDA-2024 | G40: 0 | H40: FD-A1-2006-J-PB-0002 | J40: A4 | K40: 1 | L40: 8 | M40: 0 | O40: PROJETO BÁSICO | P40: SISTEMA AUTOMAÇÃO / OUTROS SISTEMAS | Q40: FOLHA DE DADOS | R40: SDACI | X40: Conforme Proposto | Z40: 854 | AA40: 46248 | AB40: 46252 | AC40: 46248 | AD40: 46252 | AE40: 46262 | AF40: 46267 | AH40: 0 | AK40: 0 | AL40: carol | AM40: carol | AN40: carol | AO40: Belo Horizonte | AP40: N.A | AQ40: carol | AR40: carol | AU40: carol | AV40: carol | AW40: carol | AX40: N/A - NÃO SE APLICA | AY40: carol | AZ40: carol | BA40: 2D | BB40: A
A41: 37 | C41: AI - Automacao E Instrumentacao | D41: FDA - Folha De Dados | E41: 64290157-6b96-496f-accb-c1cef7bb3c5a | F41: BL1132-0001-AI-FDA-2025 | G41: 0 | H41: FD-A1-2006-J-PB-0004 | J41: A4 | K41: 1 | L41: 8 | M41: 0 | O41: PROJETO BÁSICO | P41: SISTEMA AUTOMAÇÃO / OUTROS SISTEMAS | Q41: FOLHA DE DADOS | R41: AUTOMAÇÃO DE SUBESTAÇÕES | X41: Conforme Proposto | Z41: 746 | AA41: 46217 | AB41: 46220 | AC41: 46217 | AD41: 46220 | AE41: 46230 | AF41: 46235 | AH41: 0 | AK41: 0 | AL41: carol | AM41: carol | AN41: carol | AO41: Belo Horizonte | AP41: N.A | AQ41: carol | AR41: carol | AU41: carol | AV41: carol | AW41: carol | AX41: N/A - NÃO SE APLICA | AY41: carol | AZ41: carol | BA41: 2D | BB41: A
A42: 38 | C42: AI - Automacao E Instrumentacao | D42: FDA - Folha De Dados | E42: 7f4ba86a-68bd-44f4-8d3a-bbd5944ff4df | F42: BL1132-0001-AI-FDA-2026 | G42: 0 | H42: FD-A1-2006-J-PB-0005 | J42: A4 | K42: 1 | L42: 8 | M42: 0 | O42: PROJETO BÁSICO | P42: SISTEMA AUTOMAÇÃO / OUTROS SISTEMAS | Q42: FOLHA DE DADOS | R42: REDE DE DADOS E TELEFONIA | X42: Conforme Proposto | Z42: 905 | AA42: 46239 | AB42: 46244 | AC42: 46239 | AD42: 46244 | AE42: 46254 | AF42: 46259 | AH42: 0 | AK42: 0 | AL42: carol | AM42: carol | AN42: carol | AO42: Belo Horizonte | AP42: N.A | AQ42: carol | AR42: carol | AU42: carol | AV42: carol | AW42: carol | AX42: N/A - NÃO SE APLICA | AY42: carol | AZ42: carol | BA42: 2D | BB42: A
...

Sheet Data Base
C1: Corte | D1: 46215
A2: imput | B2: imput | C2: imput | D2: imput | F2: fórmula | G2: fórmula | H2: fórmula | I2: fórmula | J2: fórmula | K2: fórmula | L2: fórmula | M2: fórmula | N2: fórmula | O2: fórmula | P2: fórmula | Q2: fórmula
A3: ITEM | B3: DISCIPLINA | C3: TIPO DE DOCUMENTO | D3: Nº DOCUMENTO EMPRESA | E3: TÍTULO | F3: FASE | G3: REV. BLOSSOM | H3: REV. CLIENTE | I3: GRD | J3: FINALIDADE ATUAL | K3: DATA EMISSÃO INICIAL | L3: DATA RETORNO | M3: DATA FINALIZAÇÃO | N3: STATUS DOCUMENTO | O3: SITUAÇÃO DOCUMENTO | P3: COM QUEM ESTÁ? | Q3: FINALIDADE RETORNO | R3: DATA EMISSÃO CR | S3: SITUAÇÃO EMISSÃO INICIAL | T3: DATA EMISSÃO BL | U3: SITUAÇÃO BL | V3: EMISSÃO FUTURA | W3: RELATÓRIO SEMANA
A4: 1 | B4: =_xlfn.XLOOKUP(D4,'LD-ELFA'!F:F,'LD-ELFA'!C:C) -> #N/A | C4: =_xlfn.XLOOKUP(D4,'LD-ELFA'!F:F,'LD-ELFA'!D:D) -> #N/A | D4: BL1132-0001-AI-DBA-2000 | E4: =_xlfn.LET(_xlpm.q,_xlfn.XLOOKUP(D4,'LD-ELFA'!F:F,'LD-ELFA'!Q:Q), _xlpm.r,_xlfn.XLOOKUP(D4,'LD-ELFA'!F:F,'LD-ELFA'!R:R), IF(_xlpm.r = "", _xlpm.q, _xlpm.q & " - " & _xlpm.r)) -> #N/A | F4: =IF(ISNUMBER(VALUE(RIGHT(D4,4))), IF(AND(VALUE(RIGHT(D4,4))>=1000, VALUE(RIGHT(D4,4))<2000), "Conceitual", IF(AND(VALUE(RIGHT(D4,4))>=2000, VALUE(RIGHT(D4,4))<3000), "Básico", IF(AND(VALUE(RIGHT(D4,4))>=3000, VALUE(RIGHT(D4,4))<4000), "Detalhado", ""))), "") -> Básico | G4: =_xlfn.XLOOKUP(D4,'LD-ELFA'!F:F,'LD-ELFA'!G:G) -> #N/A | H4: =_xlfn.XLOOKUP(D4,'LD-ELFA'!F:F,'LD-ELFA'!I:I) -> #N/A | I4: =IF(_xlfn.XLOOKUP(D4,'LD-ELFA'!F:F,'LD-ELFA'!T:T)="","",_xlfn.XLOOKUP(D4,'LD-ELFA'!F:F,'LD-ELFA'!T:T)) -> #N/A | J4: =IF(K4="Documento a emitir", "",_xlfn.XLOOKUP(D4,'LD-ELFA'!F:F,'LD-ELFA'!N:N)) -> #N/A | K4: =IF(_xlfn.XLOOKUP($D4,'LD-ELFA'!F:F,'LD-ELFA'!U:U)="","Documento a emitir",_xlfn.XLOOKUP($D4,'LD-ELFA'!F:F,'LD-ELFA'!U:U)) -> #N/A | L4: =IF(K4="Documento a emitir","Documento a emitir",IF(K4<>"Documento a emitir",IF(_xlfn.XLOOKUP(D4,'LD-ELFA'!F:F,'LD-ELFA'!W:W)="","",_xlfn.XLOOKUP(D4,'LD-ELFA'!F:F,'LD-ELFA'!W:W)),"")) -> #N/A | M4: =IF(K4="Documento a emitir","",IF(AND(Q4="APC-R - APC-R - Aprovado com Comentários (Retornar para uma nova Aprovação)",Q4="APC-L - APC-L - Aprovado com Comentários (Retornar Aprovado)"),"",IF(OR(_xlfn.XLOOKUP(D4,'LD-ELFA'!F:F,'LD-ELFA'!N:N)="PARA CONHECIMENTO",_xlfn.XLOOKUP(D4,'LD-ELFA'!F:F,'LD-ELFA'!N:N)="PARA CONSTRUÇÃO",_xlfn.XLOOKUP(D4,'LD-ELFA'!F:F,'LD-ELFA'!N:N)="PARA COTAÇÃO",_xlfn.XLOOKUP(D4,'LD-ELFA'!F:F,'LD-ELFA'!N:N)="CANCELADO"),_xlfn.XLOOKUP(D4,'LD-ELFA'!F:F,'LD-ELFA'!U:U),IF(AND(L4="",J4<>"PARA APROVAÇÃO"),"","")))) -> #N/A | N4: =IF(O4="Documento Concluído","Documento Concluído",IF(O4="Cliente - Atendimento de Comentário",IF(TODAY()<=(K4+3),"No prazo","Atrasado"),IF(O4="Cliente - Atendimento de Comentário",IF(TODAY()<=(WORKDAY(K4,3,0)),"No prazo","Atrasado"),IF(O4="Blossom - Emissão Final",IF(TODAY()<=(WORKDAY(L4,3,0)),"No prazo","Atrasado"),IF(O4="Blossom - Atendimento de Comentário",IF(TODAY()<=(WORKDAY(L4,3,0)),"No prazo","Atrasado"),IF(O4="Blossom - Documento a emitir","Documento a Emitir",IF(O4="Documento Removido","Documento Removido","ERRO"))))))) -> Documento Removido | O4: =IF(R4="Documento Removido","Documento Removido",IF(M4<>"","Documento Concluído",IF(AND(M4="",Q4="PARA APROVAÇÃO"),"Blossom - Emissão Final",IF(AND(M4="",Q4="APC-L - APC-L - Aprovado com Comentários (Retornar Aprovado)",Q4="APC-R - APC-R - Aprovado com Comentários (Retornar para uma nova Aprovação)"),"Blossom - Atendimento de Comentário",IF(AND(L4<>"",J4="PARA APROVAÇÃO"),"Blossom - Atendimento de Comentário",IF(AND(L4<>"",J4="PRELIMINAR"),"Blossom - Atendimento de Comentário",IF(AND(L4="",J4<>"PARA APROVAÇÃO"),"Cliente - Atendimento de Comentário",IF(AND(L4="",J4<>"PRELIMINAR"),"Cliente - Atendimento de Comentário",IF(AND(K4<>"Documento a emitir",J4="PARA APROVAÇÃO"),"Cliente - Atendimento de Comentário",IF(K4="Documento a emitir","Blossom - Documento a emitir","ERRO")))))))))) -> Documento Removido | P4: =IF(O4="Documento finalizado","Documento finalizado",IF(ISNUMBER(FIND("Cliente",O4)),"Circlua","Blossom")) -> Blossom | Q4: =IF(_xlfn.XLOOKUP(D4,'LD-ELFA'!F:F,'LD-ELFA'!V:V)="","",_xlfn.XLOOKUP(D4,'LD-ELFA'!F:F,'LD-ELFA'!V:V)) -> #N/A | R4: =IFERROR(IF(I4<>"","Documento Emitido",_xlfn.XLOOKUP(D4,Cronograma!P:P,Cronograma!Q:Q)),"Documento Removido") -> Documento Removido | S4: =IFERROR(IF(K4<>"Documento a emitir","Documento Emitido",IF(R4<TODAY(),"Emissão Atrasada","No prazo")),"Documento Removido") -> Documento Removido | T4: =IFERROR(IF(I4<>"","Documento Emitido",_xlfn.XLOOKUP(D4,Cronograma!P:P,Cronograma!R:R)),"Documento Removido") -> Documento Removido | U4: =IFERROR(IF(K4<>"Documento a emitir","Documento Emitido",IF(T4<R4,"Emissão Atrasada","No prazo")),"Documento Removido") -> Documento Removido | V4: =IF(R4="Documento Emitido","Documento Emitido", IF(R4="Documento Removido","Documento Removido", IF(AND(R4-$D$1>=0,R4-$D$1<=7),"Semana 1", IF(AND(R4-$D$1>7,R4-$D$1<=14),"Semana 2",IF(AND(R4-$D$1>14,R4-$D$1<=21),"Semana 3",""))))) -> Documento Removido | W4: =IF(OR(K4="Documento a emitir", K4="Documento Emitido"), "", IF(AND(ISNUMBER(K4), K4>=TODAY()-WEEKDAY(TODAY(),2)-6, K4<=TODAY()-WEEKDAY(TODAY(),2)+5), IF(G4=0, "Emissão Semana", "Atendimento de Comentário"), "")) -> #N/A
A5: 2 | B5: =_xlfn.XLOOKUP(D5,'LD-ELFA'!F:F,'LD-ELFA'!C:C) -> #N/A | C5: =_xlfn.XLOOKUP(D5,'LD-ELFA'!F:F,'LD-ELFA'!D:D) -> #N/A | D5: BL1132-0001-AI-DBA-2001 | E5: =_xlfn.LET(_xlpm.q,_xlfn.XLOOKUP(D5,'LD-ELFA'!F:F,'LD-ELFA'!Q:Q), _xlpm.r,_xlfn.XLOOKUP(D5,'LD-ELFA'!F:F,'LD-ELFA'!R:R), IF(_xlpm.r = "", _xlpm.q, _xlpm.q & " - " & _xlpm.r)) -> #N/A | F5: =IF(ISNUMBER(VALUE(RIGHT(D5,4))), IF(AND(VALUE(RIGHT(D5,4))>=1000, VALUE(RIGHT(D5,4))<2000), "Conceitual", IF(AND(VALUE(RIGHT(D5,4))>=2000, VALUE(RIGHT(D5,4))<3000), "Básico", IF(AND(VALUE(RIGHT(D5,4))>=3000, VALUE(RIGHT(D5,4))<4000), "Detalhado", ""))), "") -> Básico | G5: =_xlfn.XLOOKUP(D5,'LD-ELFA'!F:F,'LD-ELFA'!G:G) -> #N/A | H5: =_xlfn.XLOOKUP(D5,'LD-ELFA'!F:F,'LD-ELFA'!I:I) -> #N/A | I5: =IF(_xlfn.XLOOKUP(D5,'LD-ELFA'!F:F,'LD-ELFA'!T:T)="","",_xlfn.XLOOKUP(D5,'LD-ELFA'!F:F,'LD-ELFA'!T:T)) -> #N/A | J5: =IF(K5="Documento a emitir", "",_xlfn.XLOOKUP(D5,'LD-ELFA'!F:F,'LD-ELFA'!N:N)) -> #N/A | K5: =IF(_xlfn.XLOOKUP($D5,'LD-ELFA'!F:F,'LD-ELFA'!U:U)="","Documento a emitir",_xlfn.XLOOKUP($D5,'LD-ELFA'!F:F,'LD-ELFA'!U:U)) -> #N/A | L5: =IF(K5="Documento a emitir","Documento a emitir",IF(K5<>"Documento a emitir",IF(_xlfn.XLOOKUP(D5,'LD-ELFA'!F:F,'LD-ELFA'!W:W)="","",_xlfn.XLOOKUP(D5,'LD-ELFA'!F:F,'LD-ELFA'!W:W)),"")) -> #N/A | M5: =IF(K5="Documento a emitir","",IF(AND(Q5="APC-R - APC-R - Aprovado com Comentários (Retornar para uma nova Aprovação)",Q5="APC-L - APC-L - Aprovado com Comentários (Retornar Aprovado)"),"",IF(OR(_xlfn.XLOOKUP(D5,'LD-ELFA'!F:F,'LD-ELFA'!N:N)="PARA CONHECIMENTO",_xlfn.XLOOKUP(D5,'LD-ELFA'!F:F,'LD-ELFA'!N:N)="PARA CONSTRUÇÃO",_xlfn.XLOOKUP(D5,'LD-ELFA'!F:F,'LD-ELFA'!N:N)="PARA COTAÇÃO",_xlfn.XLOOKUP(D5,'LD-ELFA'!F:F,'LD-ELFA'!N:N)="CANCELADO"),_xlfn.XLOOKUP(D5,'LD-ELFA'!F:F,'LD-ELFA'!U:U),IF(AND(L5="",J5<>"PARA APROVAÇÃO"),"","")))) -> #N/A | N5: =IF(O5="Documento Concluído","Documento Concluído",IF(O5="Cliente - Atendimento de Comentário",IF(TODAY()<=(K5+3),"No prazo","Atrasado"),IF(O5="Cliente - Atendimento de Comentário",IF(TODAY()<=(WORKDAY(K5,3,0)),"No prazo","Atrasado"),IF(O5="Blossom - Emissão Final",IF(TODAY()<=(WORKDAY(L5,3,0)),"No prazo","Atrasado"),IF(O5="Blossom - Atendimento de Comentário",IF(TODAY()<=(WORKDAY(L5,3,0)),"No prazo","Atrasado"),IF(O5="Blossom - Documento a emitir","Documento a Emitir",IF(O5="Documento Removido","Documento Removido","ERRO"))))))) -> Documento Removido | O5: =IF(R5="Documento Removido","Documento Removido",IF(M5<>"","Documento Concluído",IF(AND(M5="",Q5="PARA APROVAÇÃO"),"Blossom - Emissão Final",IF(AND(M5="",Q5="APC-L - APC-L - Aprovado com Comentários (Retornar Aprovado)",Q5="APC-R - APC-R - Aprovado com Comentários (Retornar para uma nova Aprovação)"),"Blossom - Atendimento de Comentário",IF(AND(L5<>"",J5="PARA APROVAÇÃO"),"Blossom - Atendimento de Comentário",IF(AND(L5<>"",J5="PRELIMINAR"),"Blossom - Atendimento de Comentário",IF(AND(L5="",J5<>"PARA APROVAÇÃO"),"Cliente - Atendimento de Comentário",IF(AND(L5="",J5<>"PRELIMINAR"),"Cliente - Atendimento de Comentário",IF(AND(K5<>"Documento a emitir",J5="PARA APROVAÇÃO"),"Cliente - Atendimento de Comentário",IF(K5="Documento a emitir","Blossom - Documento a emitir","ERRO")))))))))) -> Documento Removido | P5: =IF(O5="Documento finalizado","Documento finalizado",IF(ISNUMBER(FIND("Cliente",O5)),"Circlua","Blossom")) -> Blossom | Q5: =IF(_xlfn.XLOOKUP(D5,'LD-ELFA'!F:F,'LD-ELFA'!V:V)="","",_xlfn.XLOOKUP(D5,'LD-ELFA'!F:F,'LD-ELFA'!V:V)) -> #N/A | R5: =IFERROR(IF(I5<>"","Documento Emitido",_xlfn.XLOOKUP(D5,Cronograma!P:P,Cronograma!Q:Q)),"Documento Removido") -> Documento Removido | S5: =IFERROR(IF(K5<>"Documento a emitir","Documento Emitido",IF(R5<TODAY(),"Emissão Atrasada","No prazo")),"Documento Removido") -> Documento Removido | T5: =IFERROR(IF(I5<>"","Documento Emitido",_xlfn.XLOOKUP(D5,Cronograma!P:P,Cronograma!R:R)),"Documento Removido") -> Documento Removido | U5: =IFERROR(IF(K5<>"Documento a emitir","Documento Emitido",IF(T5<R5,"Emissão Atrasada","No prazo")),"Documento Removido") -> Documento Removido | V5: =IF(R5="Documento Emitido","Documento Emitido", IF(R5="Documento Removido","Documento Removido", IF(AND(R5-$D$1>=0,R5-$D$1<=7),"Semana 1", IF(AND(R5-$D$1>7,R5-$D$1<=14),"Semana 2",IF(AND(R5-$D$1>14,R5-$D$1<=21),"Semana 3",""))))) -> Documento Removido | W5: =IF(OR(K5="Documento a emitir", K5="Documento Emitido"), "", IF(AND(ISNUMBER(K5), K5>=TODAY()-WEEKDAY(TODAY(),2)-6, K5<=TODAY()-WEEKDAY(TODAY(),2)+5), IF(G5=0, "Emissão Semana", "Atendimento de Comentário"), "")) -> #N/A
A6: 3 | B6: =_xlfn.XLOOKUP(D6,'LD-ELFA'!F:F,'LD-ELFA'!C:C) -> #N/A | C6: =_xlfn.XLOOKUP(D6,'LD-ELFA'!F:F,'LD-ELFA'!D:D) -> #N/A | D6: BL1132-0001-AI-DBA-2002 | E6: =_xlfn.LET(_xlpm.q,_xlfn.XLOOKUP(D6,'LD-ELFA'!F:F,'LD-ELFA'!Q:Q), _xlpm.r,_xlfn.XLOOKUP(D6,'LD-ELFA'!F:F,'LD-ELFA'!R:R), IF(_xlpm.r = "", _xlpm.q, _xlpm.q & " - " & _xlpm.r)) -> #N/A | F6: =IF(ISNUMBER(VALUE(RIGHT(D6,4))), IF(AND(VALUE(RIGHT(D6,4))>=1000, VALUE(RIGHT(D6,4))<2000), "Conceitual", IF(AND(VALUE(RIGHT(D6,4))>=2000, VALUE(RIGHT(D6,4))<3000), "Básico", IF(AND(VALUE(RIGHT(D6,4))>=3000, VALUE(RIGHT(D6,4))<4000), "Detalhado", ""))), "") -> Básico | G6: =_xlfn.XLOOKUP(D6,'LD-ELFA'!F:F,'LD-ELFA'!G:G) -> #N/A | H6: =_xlfn.XLOOKUP(D6,'LD-ELFA'!F:F,'LD-ELFA'!I:I) -> #N/A | I6: =IF(_xlfn.XLOOKUP(D6,'LD-ELFA'!F:F,'LD-ELFA'!T:T)="","",_xlfn.XLOOKUP(D6,'LD-ELFA'!F:F,'LD-ELFA'!T:T)) -> #N/A | J6: =IF(K6="Documento a emitir", "",_xlfn.XLOOKUP(D6,'LD-ELFA'!F:F,'LD-ELFA'!N:N)) -> #N/A | K6: =IF(_xlfn.XLOOKUP($D6,'LD-ELFA'!F:F,'LD-ELFA'!U:U)="","Documento a emitir",_xlfn.XLOOKUP($D6,'LD-ELFA'!F:F,'LD-ELFA'!U:U)) -> #N/A | L6: =IF(K6="Documento a emitir","Documento a emitir",IF(K6<>"Documento a emitir",IF(_xlfn.XLOOKUP(D6,'LD-ELFA'!F:F,'LD-ELFA'!W:W)="","",_xlfn.XLOOKUP(D6,'LD-ELFA'!F:F,'LD-ELFA'!W:W)),"")) -> #N/A | M6: =IF(K6="Documento a emitir","",IF(AND(Q6="APC-R - APC-R - Aprovado com Comentários (Retornar para uma nova Aprovação)",Q6="APC-L - APC-L - Aprovado com Comentários (Retornar Aprovado)"),"",IF(OR(_xlfn.XLOOKUP(D6,'LD-ELFA'!F:F,'LD-ELFA'!N:N)="PARA CONHECIMENTO",_xlfn.XLOOKUP(D6,'LD-ELFA'!F:F,'LD-ELFA'!N:N)="PARA CONSTRUÇÃO",_xlfn.XLOOKUP(D6,'LD-ELFA'!F:F,'LD-ELFA'!N:N)="PARA COTAÇÃO",_xlfn.XLOOKUP(D6,'LD-ELFA'!F:F,'LD-ELFA'!N:N)="CANCELADO"),_xlfn.XLOOKUP(D6,'LD-ELFA'!F:F,'LD-ELFA'!U:U),IF(AND(L6="",J6<>"PARA APROVAÇÃO"),"","")))) -> #N/A | N6: =IF(O6="Documento Concluído","Documento Concluído",IF(O6="Cliente - Atendimento de Comentário",IF(TODAY()<=(K6+3),"No prazo","Atrasado"),IF(O6="Cliente - Atendimento de Comentário",IF(TODAY()<=(WORKDAY(K6,3,0)),"No prazo","Atrasado"),IF(O6="Blossom - Emissão Final",IF(TODAY()<=(WORKDAY(L6,3,0)),"No prazo","Atrasado"),IF(O6="Blossom - Atendimento de Comentário",IF(TODAY()<=(WORKDAY(L6,3,0)),"No prazo","Atrasado"),IF(O6="Blossom - Documento a emitir","Documento a Emitir",IF(O6="Documento Removido","Documento Removido","ERRO"))))))) -> Documento Removido | O6: =IF(R6="Documento Removido","Documento Removido",IF(M6<>"","Documento Concluído",IF(AND(M6="",Q6="PARA APROVAÇÃO"),"Blossom - Emissão Final",IF(AND(M6="",Q6="APC-L - APC-L - Aprovado com Comentários (Retornar Aprovado)",Q6="APC-R - APC-R - Aprovado com Comentários (Retornar para uma nova Aprovação)"),"Blossom - Atendimento de Comentário",IF(AND(L6<>"",J6="PARA APROVAÇÃO"),"Blossom - Atendimento de Comentário",IF(AND(L6<>"",J6="PRELIMINAR"),"Blossom - Atendimento de Comentário",IF(AND(L6="",J6<>"PARA APROVAÇÃO"),"Cliente - Atendimento de Comentário",IF(AND(L6="",J6<>"PRELIMINAR"),"Cliente - Atendimento de Comentário",IF(AND(K6<>"Documento a emitir",J6="PARA APROVAÇÃO"),"Cliente - Atendimento de Comentário",IF(K6="Documento a emitir","Blossom - Documento a emitir","ERRO")))))))))) -> Documento Removido | P6: =IF(O6="Documento finalizado","Documento finalizado",IF(ISNUMBER(FIND("Cliente",O6)),"Circlua","Blossom")) -> Blossom | Q6: =IF(_xlfn.XLOOKUP(D6,'LD-ELFA'!F:F,'LD-ELFA'!V:V)="","",_xlfn.XLOOKUP(D6,'LD-ELFA'!F:F,'LD-ELFA'!V:V)) -> #N/A | R6: =IFERROR(IF(I6<>"","Documento Emitido",_xlfn.XLOOKUP(D6,Cronograma!P:P,Cronograma!Q:Q)),"Documento Removido") -> Documento Removido | S6: =IFERROR(IF(K6<>"Documento a emitir","Documento Emitido",IF(R6<TODAY(),"Emissão Atrasada","No prazo")),"Documento Removido") -> Documento Removido | T6: =IFERROR(IF(I6<>"","Documento Emitido",_xlfn.XLOOKUP(D6,Cronograma!P:P,Cronograma!R:R)),"Documento Removido") -> Documento Removido | U6: =IFERROR(IF(K6<>"Documento a emitir","Documento Emitido",IF(T6<R6,"Emissão Atrasada","No prazo")),"Documento Removido") -> Documento Removido | V6: =IF(R6="Documento Emitido","Documento Emitido", IF(R6="Documento Removido","Documento Removido", IF(AND(R6-$D$1>=0,R6-$D$1<=7),"Semana 1", IF(AND(R6-$D$1>7,R6-$D$1<=14),"Semana 2",IF(AND(R6-$D$1>14,R6-$D$1<=21),"Semana 3",""))))) -> Documento Removido | W6: =IF(OR(K6="Documento a emitir", K6="Documento Emitido"), "", IF(AND(ISNUMBER(K6), K6>=TODAY()-WEEKDAY(TODAY(),2)-6, K6<=TODAY()-WEEKDAY(TODAY(),2)+5), IF(G6=0, "Emissão Semana", "Atendimento de Comentário"), "")) -> #N/A
A7: 4 | B7: =_xlfn.XLOOKUP(D7,'LD-ELFA'!F:F,'LD-ELFA'!C:C) -> #N/A | C7: =_xlfn.XLOOKUP(D7,'LD-ELFA'!F:F,'LD-ELFA'!D:D) -> #N/A | D7: BL1132-0001-AI-DIN-2000 | E7: =_xlfn.LET(_xlpm.q,_xlfn.XLOOKUP(D7,'LD-ELFA'!F:F,'LD-ELFA'!Q:Q), _xlpm.r,_xlfn.XLOOKUP(D7,'LD-ELFA'!F:F,'LD-ELFA'!R:R), IF(_xlpm.r = "", _xlpm.q, _xlpm.q & " - " & _xlpm.r)) -> #N/A | F7: =IF(ISNUMBER(VALUE(RIGHT(D7,4))), IF(AND(VALUE(RIGHT(D7,4))>=1000, VALUE(RIGHT(D7,4))<2000), "Conceitual", IF(AND(VALUE(RIGHT(D7,4))>=2000, VALUE(RIGHT(D7,4))<3000), "Básico", IF(AND(VALUE(RIGHT(D7,4))>=3000, VALUE(RIGHT(D7,4))<4000), "Detalhado", ""))), "") -> Básico | G7: =_xlfn.XLOOKUP(D7,'LD-ELFA'!F:F,'LD-ELFA'!G:G) -> #N/A | H7: =_xlfn.XLOOKUP(D7,'LD-ELFA'!F:F,'LD-ELFA'!I:I) -> #N/A | I7: =IF(_xlfn.XLOOKUP(D7,'LD-ELFA'!F:F,'LD-ELFA'!T:T)="","",_xlfn.XLOOKUP(D7,'LD-ELFA'!F:F,'LD-ELFA'!T:T)) -> #N/A | J7: =IF(K7="Documento a emitir", "",_xlfn.XLOOKUP(D7,'LD-ELFA'!F:F,'LD-ELFA'!N:N)) -> #N/A | K7: =IF(_xlfn.XLOOKUP($D7,'LD-ELFA'!F:F,'LD-ELFA'!U:U)="","Documento a emitir",_xlfn.XLOOKUP($D7,'LD-ELFA'!F:F,'LD-ELFA'!U:U)) -> #N/A | L7: =IF(K7="Documento a emitir","Documento a emitir",IF(K7<>"Documento a emitir",IF(_xlfn.XLOOKUP(D7,'LD-ELFA'!F:F,'LD-ELFA'!W:W)="","",_xlfn.XLOOKUP(D7,'LD-ELFA'!F:F,'LD-ELFA'!W:W)),"")) -> #N/A | M7: =IF(K7="Documento a emitir","",IF(AND(Q7="APC-R - APC-R - Aprovado com Comentários (Retornar para uma nova Aprovação)",Q7="APC-L - APC-L - Aprovado com Comentários (Retornar Aprovado)"),"",IF(OR(_xlfn.XLOOKUP(D7,'LD-ELFA'!F:F,'LD-ELFA'!N:N)="PARA CONHECIMENTO",_xlfn.XLOOKUP(D7,'LD-ELFA'!F:F,'LD-ELFA'!N:N)="PARA CONSTRUÇÃO",_xlfn.XLOOKUP(D7,'LD-ELFA'!F:F,'LD-ELFA'!N:N)="PARA COTAÇÃO",_xlfn.XLOOKUP(D7,'LD-ELFA'!F:F,'LD-ELFA'!N:N)="CANCELADO"),_xlfn.XLOOKUP(D7,'LD-ELFA'!F:F,'LD-ELFA'!U:U),IF(AND(L7="",J7<>"PARA APROVAÇÃO"),"","")))) -> #N/A | N7: =IF(O7="Documento Concluído","Documento Concluído",IF(O7="Cliente - Atendimento de Comentário",IF(TODAY()<=(K7+3),"No prazo","Atrasado"),IF(O7="Cliente - Atendimento de Comentário",IF(TODAY()<=(WORKDAY(K7,3,0)),"No prazo","Atrasado"),IF(O7="Blossom - Emissão Final",IF(TODAY()<=(WORKDAY(L7,3,0)),"No prazo","Atrasado"),IF(O7="Blossom - Atendimento de Comentário",IF(TODAY()<=(WORKDAY(L7,3,0)),"No prazo","Atrasado"),IF(O7="Blossom - Documento a emitir","Documento a Emitir",IF(O7="Documento Removido","Documento Removido","ERRO"))))))) -> Documento Removido | O7: =IF(R7="Documento Removido","Documento Removido",IF(M7<>"","Documento Concluído",IF(AND(M7="",Q7="PARA APROVAÇÃO"),"Blossom - Emissão Final",IF(AND(M7="",Q7="APC-L - APC-L - Aprovado com Comentários (Retornar Aprovado)",Q7="APC-R - APC-R - Aprovado com Comentários (Retornar para uma nova Aprovação)"),"Blossom - Atendimento de Comentário",IF(AND(L7<>"",J7="PARA APROVAÇÃO"),"Blossom - Atendimento de Comentário",IF(AND(L7<>"",J7="PRELIMINAR"),"Blossom - Atendimento de Comentário",IF(AND(L7="",J7<>"PARA APROVAÇÃO"),"Cliente - Atendimento de Comentário",IF(AND(L7="",J7<>"PRELIMINAR"),"Cliente - Atendimento de Comentário",IF(AND(K7<>"Documento a emitir",J7="PARA APROVAÇÃO"),"Cliente - Atendimento de Comentário",IF(K7="Documento a emitir","Blossom - Documento a emitir","ERRO")))))))))) -> Documento Removido | P7: =IF(O7="Documento finalizado","Documento finalizado",IF(ISNUMBER(FIND("Cliente",O7)),"Circlua","Blossom")) -> Blossom | Q7: =IF(_xlfn.XLOOKUP(D7,'LD-ELFA'!F:F,'LD-ELFA'!V:V)="","",_xlfn.XLOOKUP(D7,'LD-ELFA'!F:F,'LD-ELFA'!V:V)) -> #N/A | R7: =IFERROR(IF(I7<>"","Documento Emitido",_xlfn.XLOOKUP(D7,Cronograma!P:P,Cronograma!Q:Q)),"Documento Removido") -> Documento Removido | S7: =IFERROR(IF(K7<>"Documento a emitir","Documento Emitido",IF(R7<TODAY(),"Emissão Atrasada","No prazo")),"Documento Removido") -> Documento Removido | T7: =IFERROR(IF(I7<>"","Documento Emitido",_xlfn.XLOOKUP(D7,Cronograma!P:P,Cronograma!R:R)),"Documento Removido") -> Documento Removido | U7: =IFERROR(IF(K7<>"Documento a emitir","Documento Emitido",IF(T7<R7,"Emissão Atrasada","No prazo")),"Documento Removido") -> Documento Removido | V7: =IF(R7="Documento Emitido","Documento Emitido", IF(R7="Documento Removido","Documento Removido", IF(AND(R7-$D$1>=0,R7-$D$1<=7),"Semana 1", IF(AND(R7-$D$1>7,R7-$D$1<=14),"Semana 2",IF(AND(R7-$D$1>14,R7-$D$1<=21),"Semana 3",""))))) -> Documento Removido | W7: =IF(OR(K7="Documento a emitir", K7="Documento Emitido"), "", IF(AND(ISNUMBER(K7), K7>=TODAY()-WEEKDAY(TODAY(),2)-6, K7<=TODAY()-WEEKDAY(TODAY(),2)+5), IF(G7=0, "Emissão Semana", "Atendimento de Comentário"), "")) -> #N/A
A8: 5 | B8: =_xlfn.XLOOKUP(D8,'LD-ELFA'!F:F,'LD-ELFA'!C:C) -> #N/A | C8: =_xlfn.XLOOKUP(D8,'LD-ELFA'!F:F,'LD-ELFA'!D:D) -> #N/A | D8: BL1132-0001-AI-DIN-2001 | E8: =_xlfn.LET(_xlpm.q,_xlfn.XLOOKUP(D8,'LD-ELFA'!F:F,'LD-ELFA'!Q:Q), _xlpm.r,_xlfn.XLOOKUP(D8,'LD-ELFA'!F:F,'LD-ELFA'!R:R), IF(_xlpm.r = "", _xlpm.q, _xlpm.q & " - " & _xlpm.r)) -> #N/A | F8: =IF(ISNUMBER(VALUE(RIGHT(D8,4))), IF(AND(VALUE(RIGHT(D8,4))>=1000, VALUE(RIGHT(D8,4))<2000), "Conceitual", IF(AND(VALUE(RIGHT(D8,4))>=2000, VALUE(RIGHT(D8,4))<3000), "Básico", IF(AND(VALUE(RIGHT(D8,4))>=3000, VALUE(RIGHT(D8,4))<4000), "Detalhado", ""))), "") -> Básico | G8: =_xlfn.XLOOKUP(D8,'LD-ELFA'!F:F,'LD-ELFA'!G:G) -> #N/A | H8: =_xlfn.XLOOKUP(D8,'LD-ELFA'!F:F,'LD-ELFA'!I:I) -> #N/A | I8: =IF(_xlfn.XLOOKUP(D8,'LD-ELFA'!F:F,'LD-ELFA'!T:T)="","",_xlfn.XLOOKUP(D8,'LD-ELFA'!F:F,'LD-ELFA'!T:T)) -> #N/A | J8: =IF(K8="Documento a emitir", "",_xlfn.XLOOKUP(D8,'LD-ELFA'!F:F,'LD-ELFA'!N:N)) -> #N/A | K8: =IF(_xlfn.XLOOKUP($D8,'LD-ELFA'!F:F,'LD-ELFA'!U:U)="","Documento a emitir",_xlfn.XLOOKUP($D8,'LD-ELFA'!F:F,'LD-ELFA'!U:U)) -> #N/A | L8: =IF(K8="Documento a emitir","Documento a emitir",IF(K8<>"Documento a emitir",IF(_xlfn.XLOOKUP(D8,'LD-ELFA'!F:F,'LD-ELFA'!W:W)="","",_xlfn.XLOOKUP(D8,'LD-ELFA'!F:F,'LD-ELFA'!W:W)),"")) -> #N/A | M8: =IF(K8="Documento a emitir","",IF(AND(Q8="APC-R - APC-R - Aprovado com Comentários (Retornar para uma nova Aprovação)",Q8="APC-L - APC-L - Aprovado com Comentários (Retornar Aprovado)"),"",IF(OR(_xlfn.XLOOKUP(D8,'LD-ELFA'!F:F,'LD-ELFA'!N:N)="PARA CONHECIMENTO",_xlfn.XLOOKUP(D8,'LD-ELFA'!F:F,'LD-ELFA'!N:N)="PARA CONSTRUÇÃO",_xlfn.XLOOKUP(D8,'LD-ELFA'!F:F,'LD-ELFA'!N:N)="PARA COTAÇÃO",_xlfn.XLOOKUP(D8,'LD-ELFA'!F:F,'LD-ELFA'!N:N)="CANCELADO"),_xlfn.XLOOKUP(D8,'LD-ELFA'!F:F,'LD-ELFA'!U:U),IF(AND(L8="",J8<>"PARA APROVAÇÃO"),"","")))) -> #N/A | N8: =IF(O8="Documento Concluído","Documento Concluído",IF(O8="Cliente - Atendimento de Comentário",IF(TODAY()<=(K8+3),"No prazo","Atrasado"),IF(O8="Cliente - Atendimento de Comentário",IF(TODAY()<=(WORKDAY(K8,3,0)),"No prazo","Atrasado"),IF(O8="Blossom - Emissão Final",IF(TODAY()<=(WORKDAY(L8,3,0)),"No prazo","Atrasado"),IF(O8="Blossom - Atendimento de Comentário",IF(TODAY()<=(WORKDAY(L8,3,0)),"No prazo","Atrasado"),IF(O8="Blossom - Documento a emitir","Documento a Emitir",IF(O8="Documento Removido","Documento Removido","ERRO"))))))) -> Documento Removido | O8: =IF(R8="Documento Removido","Documento Removido",IF(M8<>"","Documento Concluído",IF(AND(M8="",Q8="PARA APROVAÇÃO"),"Blossom - Emissão Final",IF(AND(M8="",Q8="APC-L - APC-L - Aprovado com Comentários (Retornar Aprovado)",Q8="APC-R - APC-R - Aprovado com Comentários (Retornar para uma nova Aprovação)"),"Blossom - Atendimento de Comentário",IF(AND(L8<>"",J8="PARA APROVAÇÃO"),"Blossom - Atendimento de Comentário",IF(AND(L8<>"",J8="PRELIMINAR"),"Blossom - Atendimento de Comentário",IF(AND(L8="",J8<>"PARA APROVAÇÃO"),"Cliente - Atendimento de Comentário",IF(AND(L8="",J8<>"PRELIMINAR"),"Cliente - Atendimento de Comentário",IF(AND(K8<>"Documento a emitir",J8="PARA APROVAÇÃO"),"Cliente - Atendimento de Comentário",IF(K8="Documento a emitir","Blossom - Documento a emitir","ERRO")))))))))) -> Documento Removido | P8: =IF(O8="Documento finalizado","Documento finalizado",IF(ISNUMBER(FIND("Cliente",O8)),"Circlua","Blossom")) -> Blossom | Q8: =IF(_xlfn.XLOOKUP(D8,'LD-ELFA'!F:F,'LD-ELFA'!V:V)="","",_xlfn.XLOOKUP(D8,'LD-ELFA'!F:F,'LD-ELFA'!V:V)) -> #N/A | R8: =IFERROR(IF(I8<>"","Documento Emitido",_xlfn.XLOOKUP(D8,Cronograma!P:P,Cronograma!Q:Q)),"Documento Removido") -> Documento Removido | S8: =IFERROR(IF(K8<>"Documento a emitir","Documento Emitido",IF(R8<TODAY(),"Emissão Atrasada","No prazo")),"Documento Removido") -> Documento Removido | T8: =IFERROR(IF(I8<>"","Documento Emitido",_xlfn.XLOOKUP(D8,Cronograma!P:P,Cronograma!R:R)),"Documento Removido") -> Documento Removido | U8: =IFERROR(IF(K8<>"Documento a emitir","Documento Emitido",IF(T8<R8,"Emissão Atrasada","No prazo")),"Documento Removido") -> Documento Removido | V8: =IF(R8="Documento Emitido","Documento Emitido", IF(R8="Documento Removido","Documento Removido", IF(AND(R8-$D$1>=0,R8-$D$1<=7),"Semana 1", IF(AND(R8-$D$1>7,R8-$D$1<=14),"Semana 2",IF(AND(R8-$D$1>14,R8-$D$1<=21),"Semana 3",""))))) -> Documento Removido | W8: =IF(OR(K8="Documento a emitir", K8="Documento Emitido"), "", IF(AND(ISNUMBER(K8), K8>=TODAY()-WEEKDAY(TODAY(),2)-6, K8<=TODAY()-WEEKDAY(TODAY(),2)+5), IF(G8=0, "Emissão Semana", "Atendimento de Comentário"), "")) -> #N/A
A9: 6 | B9: =_xlfn.XLOOKUP(D9,'LD-ELFA'!F:F,'LD-ELFA'!C:C) -> #N/A | C9: =_xlfn.XLOOKUP(D9,'LD-ELFA'!F:F,'LD-ELFA'!D:D) -> #N/A | D9: BL1132-0001-AI-DIN-2002 | E9: =_xlfn.LET(_xlpm.q,_xlfn.XLOOKUP(D9,'LD-ELFA'!F:F,'LD-ELFA'!Q:Q), _xlpm.r,_xlfn.XLOOKUP(D9,'LD-ELFA'!F:F,'LD-ELFA'!R:R), IF(_xlpm.r = "", _xlpm.q, _xlpm.q & " - " & _xlpm.r)) -> #N/A | F9: =IF(ISNUMBER(VALUE(RIGHT(D9,4))), IF(AND(VALUE(RIGHT(D9,4))>=1000, VALUE(RIGHT(D9,4))<2000), "Conceitual", IF(AND(VALUE(RIGHT(D9,4))>=2000, VALUE(RIGHT(D9,4))<3000), "Básico", IF(AND(VALUE(RIGHT(D9,4))>=3000, VALUE(RIGHT(D9,4))<4000), "Detalhado", ""))), "") -> Básico | G9: =_xlfn.XLOOKUP(D9,'LD-ELFA'!F:F,'LD-ELFA'!G:G) -> #N/A | H9: =_xlfn.XLOOKUP(D9,'LD-ELFA'!F:F,'LD-ELFA'!I:I) -> #N/A | I9: =IF(_xlfn.XLOOKUP(D9,'LD-ELFA'!F:F,'LD-ELFA'!T:T)="","",_xlfn.XLOOKUP(D9,'LD-ELFA'!F:F,'LD-ELFA'!T:T)) -> #N/A | J9: =IF(K9="Documento a emitir", "",_xlfn.XLOOKUP(D9,'LD-ELFA'!F:F,'LD-ELFA'!N:N)) -> #N/A | K9: =IF(_xlfn.XLOOKUP($D9,'LD-ELFA'!F:F,'LD-ELFA'!U:U)="","Documento a emitir",_xlfn.XLOOKUP($D9,'LD-ELFA'!F:F,'LD-ELFA'!U:U)) -> #N/A | L9: =IF(K9="Documento a emitir","Documento a emitir",IF(K9<>"Documento a emitir",IF(_xlfn.XLOOKUP(D9,'LD-ELFA'!F:F,'LD-ELFA'!W:W)="","",_xlfn.XLOOKUP(D9,'LD-ELFA'!F:F,'LD-ELFA'!W:W)),"")) -> #N/A | M9: =IF(K9="Documento a emitir","",IF(AND(Q9="APC-R - APC-R - Aprovado com Comentários (Retornar para uma nova Aprovação)",Q9="APC-L - APC-L - Aprovado com Comentários (Retornar Aprovado)"),"",IF(OR(_xlfn.XLOOKUP(D9,'LD-ELFA'!F:F,'LD-ELFA'!N:N)="PARA CONHECIMENTO",_xlfn.XLOOKUP(D9,'LD-ELFA'!F:F,'LD-ELFA'!N:N)="PARA CONSTRUÇÃO",_xlfn.XLOOKUP(D9,'LD-ELFA'!F:F,'LD-ELFA'!N:N)="PARA COTAÇÃO",_xlfn.XLOOKUP(D9,'LD-ELFA'!F:F,'LD-ELFA'!N:N)="CANCELADO"),_xlfn.XLOOKUP(D9,'LD-ELFA'!F:F,'LD-ELFA'!U:U),IF(AND(L9="",J9<>"PARA APROVAÇÃO"),"","")))) -> #N/A | N9: =IF(O9="Documento Concluído","Documento Concluído",IF(O9="Cliente - Atendimento de Comentário",IF(TODAY()<=(K9+3),"No prazo","Atrasado"),IF(O9="Cliente - Atendimento de Comentário",IF(TODAY()<=(WORKDAY(K9,3,0)),"No prazo","Atrasado"),IF(O9="Blossom - Emissão Final",IF(TODAY()<=(WORKDAY(L9,3,0)),"No prazo","Atrasado"),IF(O9="Blossom - Atendimento de Comentário",IF(TODAY()<=(WORKDAY(L9,3,0)),"No prazo","Atrasado"),IF(O9="Blossom - Documento a emitir","Documento a Emitir",IF(O9="Documento Removido","Documento Removido","ERRO"))))))) -> Documento Removido | O9: =IF(R9="Documento Removido","Documento Removido",IF(M9<>"","Documento Concluído",IF(AND(M9="",Q9="PARA APROVAÇÃO"),"Blossom - Emissão Final",IF(AND(M9="",Q9="APC-L - APC-L - Aprovado com Comentários (Retornar Aprovado)",Q9="APC-R - APC-R - Aprovado com Comentários (Retornar para uma nova Aprovação)"),"Blossom - Atendimento de Comentário",IF(AND(L9<>"",J9="PARA APROVAÇÃO"),"Blossom - Atendimento de Comentário",IF(AND(L9<>"",J9="PRELIMINAR"),"Blossom - Atendimento de Comentário",IF(AND(L9="",J9<>"PARA APROVAÇÃO"),"Cliente - Atendimento de Comentário",IF(AND(L9="",J9<>"PRELIMINAR"),"Cliente - Atendimento de Comentário",IF(AND(K9<>"Documento a emitir",J9="PARA APROVAÇÃO"),"Cliente - Atendimento de Comentário",IF(K9="Documento a emitir","Blossom - Documento a emitir","ERRO")))))))))) -> Documento Removido | P9: =IF(O9="Documento finalizado","Documento finalizado",IF(ISNUMBER(FIND("Cliente",O9)),"Circlua","Blossom")) -> Blossom | Q9: =IF(_xlfn.XLOOKUP(D9,'LD-ELFA'!F:F,'LD-ELFA'!V:V)="","",_xlfn.XLOOKUP(D9,'LD-ELFA'!F:F,'LD-ELFA'!V:V)) -> #N/A | R9: =IFERROR(IF(I9<>"","Documento Emitido",_xlfn.XLOOKUP(D9,Cronograma!P:P,Cronograma!Q:Q)),"Documento Removido") -> Documento Removido | S9: =IFERROR(IF(K9<>"Documento a emitir","Documento Emitido",IF(R9<TODAY(),"Emissão Atrasada","No prazo")),"Documento Removido") -> Documento Removido | T9: =IFERROR(IF(I9<>"","Documento Emitido",_xlfn.XLOOKUP(D9,Cronograma!P:P,Cronograma!R:R)),"Documento Removido") -> Documento Removido | U9: =IFERROR(IF(K9<>"Documento a emitir","Documento Emitido",IF(T9<R9,"Emissão Atrasada","No prazo")),"Documento Removido") -> Documento Removido | V9: =IF(R9="Documento Emitido","Documento Emitido", IF(R9="Documento Removido","Documento Removido", IF(AND(R9-$D$1>=0,R9-$D$1<=7),"Semana 1", IF(AND(R9-$D$1>7,R9-$D$1<=14),"Semana 2",IF(AND(R9-$D$1>14,R9-$D$1<=21),"Semana 3",""))))) -> Documento Removido | W9: =IF(OR(K9="Documento a emitir", K9="Documento Emitido"), "", IF(AND(ISNUMBER(K9), K9>=TODAY()-WEEKDAY(TODAY(),2)-6, K9<=TODAY()-WEEKDAY(TODAY(),2)+5), IF(G9=0, "Emissão Semana", "Atendimento de Comentário"), "")) -> #N/A
